Workbook

Sheet Assumptions
A1: VIRIYA Financial Model — Assumptions (5-year)
A2: แก้ช่องเหลือง → P&L / Cash / BS / Summary recalculate อัตโนมัติ
A4: รายการ (รายได้) | B4: ค่า | C4: หมายเหตุ
A5: Starter tier — ราคา/เดือน (THB) | B5: 6500 | C5: ≤100 นิสิต
A6: Pro tier — ราคา/เดือน (THB) | B6: 15000 | C6: 100-300 นิสิต
A7: Enterprise tier — ราคา/เดือน (THB) | B7: 32500 | C7: >300 นิสิต
A8: สัดส่วน Starter | B8: 0.6
A9: สัดส่วน Pro | B9: 0.3
A10: สัดส่วน Enterprise | B10: 0.1
A11: Setup fee ต่อ tenant (THB) | B11: 25000 | C11: ครั้งเดียว
A12: ค่าเฉลี่ยถ่วงน้ำหนัก/tenant/mo | B12: =Assumptions!$B$5*Assumptions!$B$8+Assumptions!$B$6*Assumptions!$B$9+Assumptions!$B$7*Assumptions!$B$10 | C12: auto
A14: รายการ (ต้นทุน) | B14: ค่า | C14: หมายเหตุ
A15: Claude Opus input — ฿/tenant/mo | B15: 1050 | C15: $5/Mtok × 6M
A16: Claude Opus output — ฿/tenant/mo | B16: 1313 | C16: $25/Mtok × 1.5M
A17: Cohere Rerank — ฿/tenant/mo | B17: 210
A18: Cohere Embed — ฿/tenant/mo | B18: 0.42
A19: Pinecone read — ฿/tenant/mo | B19: 8
A20: Pinecone Standard plan | B20: 1750 | C20: $50/mo
A21: GCP Cloud Run | B21: 1050 | C21: $30/mo
A22: GCP Firestore + CS | B22: 350
A23: Domain + SSL + monitoring | B23: 350
A24: Tech lead / คน/เดือน | B24: 80000
A25: Customer/biz / คน/เดือน | B25: 40000
A26: ต้นทุน onboard ใหม่ (ครั้งเดียว) | B26: 5000
A27: รวมต้นทุนผันแปร/tenant/mo | B27: =Assumptions!$B$15+Assumptions!$B$16+Assumptions!$B$17+Assumptions!$B$18+Assumptions!$B$19
A28: รวมต้นทุนคงที่ระบบ/mo | B28: =Assumptions!$B$20+Assumptions!$B$21+Assumptions!$B$22+Assumptions!$B$23
A29: รวมเงินเดือนทีมเริ่มต้น/mo | B29: =Assumptions!$B$24+Assumptions!$B$25
A31: รายการ (การเติบโต/ภาษี/เงินกู้/ปันผล) | B31: ค่า | C31: หมายเหตุ
A32: Tenant ใหม่/mo ปีที่ 1 | B32: 2
A33: Tenant ใหม่/mo ปีที่ 2 | B33: 2
A34: Tenant ใหม่/mo ปีที่ 3 | B34: 1
A35: Tenant ใหม่/mo ปีที่ 4 | B35: 1
A36: Tenant ใหม่/mo ปีที่ 5 | B36: 1
A37: อัตราภาษีนิติบุคคล | B37: 0.2 | C37: CIT 20%
A38: WACC (คิดลด NPV) | B38: 0.12 | C38: equity 67% × 15% + debt 33% × 4%
A39: เงินทุนผู้ถือหุ้น (THB) | B39: 2000000 | C39: 2,000 หุ้น × 1,000 × 4 คน
A40: เงินกู้ระยะยาว (THB) | B40: 1000000 | C40: ภาครัฐ
A41: อัตราดอกเบี้ยเงินกู้ | B41: 0.05 | C41: 5% ต่อปี
A42: ระยะเวลาผ่อน (ปี) | B42: 5
A43: นโยบายปันผล (ของกำไรสุทธิ) | B43: 0.3 | C43: 30%
...

Sheet Loan
A1: Loan Amortization — 5 ปี
A3: ปี | B3: เงินต้นคงค้างต้นปี | C3: ดอกเบี้ย | D3: เงินต้นที่ชำระ | E3: ชำระรวมรายปี | F3: เงินต้นคงค้างสิ้นปี
A4: 1 | B4: =Assumptions!$B$40 | C4: =B4*Assumptions!$B$41 | D4: =E4-C4 | E4: =-PMT(Assumptions!$B$41,Assumptions!$B$42,Assumptions!$B$40) | F4: =B4-D4
A5: 2 | B5: =F4 | C5: =B5*Assumptions!$B$41 | D5: =E5-C5 | E5: =-PMT(Assumptions!$B$41,Assumptions!$B$42,Assumptions!$B$40) | F5: =B5-D5
A6: 3 | B6: =F5 | C6: =B6*Assumptions!$B$41 | D6: =E6-C6 | E6: =-PMT(Assumptions!$B$41,Assumptions!$B$42,Assumptions!$B$40) | F6: =B6-D6
A7: 4 | B7: =F6 | C7: =B7*Assumptions!$B$41 | D7: =E7-C7 | E7: =-PMT(Assumptions!$B$41,Assumptions!$B$42,Assumptions!$B$40) | F7: =B7-D7
A8: 5 | B8: =F7 | C8: =B8*Assumptions!$B$41 | D8: =E8-C8 | E8: =-PMT(Assumptions!$B$41,Assumptions!$B$42,Assumptions!$B$40) | F8: =B8-D8
A9: รวม | C9: =SUM(C4:C8) | D9: =SUM(D4:D8) | E9: =SUM(E4:E8)

Sheet Assets
A1: สินทรัพย์ที่ใช้ในการประกอบธุรกิจ
A3: รายการ | B3: รายละเอียด | C3: มูลค่า (THB) | D3: อายุ (ปี) | E3: ค่าเสื่อม/ปี
A4: ซอฟต์แวร์ระบบ VIRIYA | B4: chat-api + ingest + admin + portal | C4: 300000 | D4: 3 | E4: =C4/D4
A5: ตราสินค้า VIRIYA | B5: logo + CI + trademark | C5: 30000 | D5: 5 | E5: =C5/D5
A6: Domain + SSL | B6: รายจ่ายต่อเนื่อง (OpEx) | C6: 5000 | D6: — | E6: 0
A7: อุปกรณ์สำนักงาน | B7: คอม + จอ + อุปกรณ์ | C7: 150000 | D7: 5 | E7: =C7/D7
A8: รวม | C8: =SUM(C4:C7) | E8: =SUM(E4:E7)

Sheet SG&A
A1: ค่าใช้จ่ายในการขายและการบริหาร (SG&A) 5 ปี
A3: รายการ | B3: ปีที่ 1 | C3: ปีที่ 2 | D3: ปีที่ 3 | E3: ปีที่ 4 | F3: ปีที่ 5
A4: ค่าใช้จ่ายในการขาย (Selling)
A5: ค่าโฆษณาออนไลน์ | B5: =Assumptions!$B$48*0.4 | C5: =Assumptions!$B$49*0.4 | D5: =Assumptions!$B$50*0.4 | E5: =Assumptions!$B$51*0.4 | F5: =Assumptions!$B$52*0.4
A6: กิจกรรมการขายและสาธิต | B6: =Assumptions!$B$48*0.3 | C6: =Assumptions!$B$49*0.3 | D6: =Assumptions!$B$50*0.3 | E6: =Assumptions!$B$51*0.3 | F6: =Assumptions!$B$52*0.3
A7: เนื้อหาการตลาด | B7: =Assumptions!$B$48*0.3 | C7: =Assumptions!$B$49*0.3 | D7: =Assumptions!$B$50*0.3 | E7: =Assumptions!$B$51*0.3 | F7: =Assumptions!$B$52*0.3
A8: รวมค่าใช้จ่ายในการขาย | B8: =SUM(B5:B7) | C8: =SUM(C5:C7) | D8: =SUM(D5:D7) | E8: =SUM(E5:E7) | F8: =SUM(F5:F7)
A10: ค่าใช้จ่ายในการบริหาร (G&A)
A11: ค่าแรงบุคลากร | B11: =Assumptions!$B$29*12 | C11: =Assumptions!$B$29*12*Assumptions!$B$58 | D11: =Assumptions!$B$29*12*Assumptions!$B$59 | E11: =Assumptions!$B$29*12*Assumptions!$B$60 | F11: =Assumptions!$B$29*12*Assumptions!$B$61
A12: ค่าเช่า + ค่าเดินทาง + สาธารณูปโภค + บัญชี/กฎหมาย | B12: =Assumptions!$B$53 | C12: =Assumptions!$B$54 | D12: =Assumptions!$B$55 | E12: =Assumptions!$B$56 | F12: =Assumptions!$B$57
A13: รวมค่าใช้จ่ายในการบริหาร | B13: =SUM(B11:B12) | C13: =SUM(C11:C12) | D13: =SUM(D11:D12) | E13: =SUM(E11:E12) | F13: =SUM(F11:F12)
A15: รวม SG&A | B15: =B8+B13 | C15: =C8+C13 | D15: =D8+D13 | E15: =E8+E13 | F15: =F8+F13

Sheet P&L
A1: งบกำไรขาดทุน 5 ปี
A3: รายการ | B3: ปีที่ 1 | C3: ปีที่ 2 | D3: ปีที่ 3 | E3: ปีที่ 4 | F3: ปีที่ 5
A4: Tenant ณ สิ้นปี | B4: =Assumptions!$B$32*12 | C4: =B4+Assumptions!$B$33*12 | D4: =C4+Assumptions!$B$34*12 | E4: =D4+Assumptions!$B$35*12 | F4: =E4+Assumptions!$B$36*12
A5: Tenant เฉลี่ย (start + growth×6.5) | B5: =0+Assumptions!$B$32*6.5 | C5: =B4+Assumptions!$B$33*6.5 | D5: =C4+Assumptions!$B$34*6.5 | E5: =D4+Assumptions!$B$35*6.5 | F5: =E4+Assumptions!$B$36*6.5
A7: รายได้
A8: ค่าสมาชิก | B8: =B5*Assumptions!$B$12*12 | C8: =C5*Assumptions!$B$12*12 | D8: =D5*Assumptions!$B$12*12 | E8: =E5*Assumptions!$B$12*12 | F8: =F5*Assumptions!$B$12*12
A9: Setup fee | B9: =Assumptions!$B$32*12*Assumptions!$B$11 | C9: =Assumptions!$B$33*12*Assumptions!$B$11 | D9: =Assumptions!$B$34*12*Assumptions!$B$11 | E9: =Assumptions!$B$35*12*Assumptions!$B$11 | F9: =Assumptions!$B$36*12*Assumptions!$B$11
A10: รวมรายได้ | B10: =B8+B9 | C10: =C8+C9 | D10: =D8+D9 | E10: =E8+E9 | F10: =F8+F9
A12: ต้นทุนผันแปร
A13: AI API + Pinecone | B13: =B5*Assumptions!$B$27*12 | C13: =C5*Assumptions!$B$27*12 | D13: =D5*Assumptions!$B$27*12 | E13: =E5*Assumptions!$B$27*12 | F13: =F5*Assumptions!$B$27*12
A14: Onboard tenant ใหม่ | B14: =Assumptions!$B$32*12*Assumptions!$B$26 | C14: =Assumptions!$B$33*12*Assumptions!$B$26 | D14: =Assumptions!$B$34*12*Assumptions!$B$26 | E14: =Assumptions!$B$35*12*Assumptions!$B$26 | F14: =Assumptions!$B$36*12*Assumptions!$B$26
A15: รวมต้นทุนผันแปร | B15: =B13+B14 | C15: =C13+C14 | D15: =D13+D14 | E15: =E13+E14 | F15: =F13+F14
A17: กำไรขั้นต้น (Gross Profit) | B17: =B10-B15 | C17: =C10-C15 | D17: =D10-D15 | E17: =E10-E15 | F17: =F10-F15
A18: อัตรากำไรขั้นต้น (%) | B18: =B17/B10 | C18: =C17/C10 | D18: =D17/D10 | E18: =E17/E10 | F18: =F17/F10
A20: ค่าใช้จ่ายในการดำเนินงาน (SG&A + infra)
A21: SG&A (link SG&A sheet) | B21: ='SG&A'!B15 | C21: ='SG&A'!C15 | D21: ='SG&A'!D15 | E21: ='SG&A'!E15 | F21: ='SG&A'!F15
A22: โครงสร้างพื้นฐานระบบ | B22: =Assumptions!$B$28*12 | C22: =Assumptions!$B$28*12 | D22: =Assumptions!$B$28*12 | E22: =Assumptions!$B$28*12 | F22: =Assumptions!$B$28*12
A23: รวม OpEx | B23: =B21+B22 | C23: =C21+C22 | D23: =D21+D22 | E23: =E21+E22 | F23: =F21+F22
A25: EBITDA (Gross - OpEx) | B25: =B17-B23 | C25: =C17-C23 | D25: =D17-D23 | E25: =E17-E23 | F25: =F17-F23
A26: ค่าเสื่อมราคา | B26: =Assumptions!$B$46 | C26: =Assumptions!$B$46 | D26: =Assumptions!$B$46 | E26: =Assumptions!$B$47 | F26: =Assumptions!$B$47
A27: EBIT (EBITDA - Dep) | B27: =B25-B26 | C27: =C25-C26 | D27: =D25-D26 | E27: =E25-E26 | F27: =F25-F26
A28: ดอกเบี้ยจ่าย (จาก Loan sheet) | B28: =Loan!C4 | C28: =Loan!C5 | D28: =Loan!C6 | E28: =Loan!C7 | F28: =Loan!C8
A29: กำไรก่อนหักภาษี (EBT) | B29: =B27-B28 | C29: =C27-C28 | D29: =D27-D28 | E29: =E27-E28 | F29: =F27-F28
A30: ภาษีเงินได้ (20% ของ EBT ถ้า +) | B30: =MAX(0, B29*Assumptions!$B$37) | C30: =MAX(0, C29*Assumptions!$B$37) | D30: =MAX(0, D29*Assumptions!$B$37) | E30: =MAX(0, E29*Assumptions!$B$37) | F30: =MAX(0, F29*Assumptions!$B$37)
A31: กำไรสุทธิ (Net Profit) | B31: =B29-B30 | C31: =C29-C30 | D31: =D29-D30 | E31: =E29-E30 | F31: =F29-F30
A32: อัตรากำไรสุทธิ (%) | B32: =B31/B10 | C32: =C31/C10 | D32: =D31/D10 | E32: =E31/E10 | F32: =F31/F10
A34: การจ่ายปันผล (30% จาก Y4) | B34: =IF(1>=Assumptions!$B$44,MAX(0,B31*Assumptions!$B$43),0) | C34: =IF(2>=Assumptions!$B$44,MAX(0,C31*Assumptions!$B$43),0) | D34: =IF(3>=Assumptions!$B$44,MAX(0,D31*Assumptions!$B$43),0) | E34: =IF(4>=Assumptions!$B$44,MAX(0,E31*Assumptions!$B$43),0) | F34: =IF(5>=Assumptions!$B$44,MAX(0,F31*Assumptions!$B$43),0)

Sheet CashFlow
A1: งบกระแสเงินสด 5 ปี
A3: รายการ | B3: ปีที่ 0 | C3: ปีที่ 1 | D3: ปีที่ 2 | E3: ปีที่ 3 | F3: ปีที่ 4 | G3: ปีที่ 5
A4: กระแสเงินสดจากการดำเนินงาน
A5: กำไรสุทธิ | B5: 0 | C5: ='P&L'!B31 | D5: ='P&L'!C31 | E5: ='P&L'!D31 | F5: ='P&L'!E31 | G5: ='P&L'!F31
A6: บวก: ค่าเสื่อมราคา | B6: 0 | C6: ='P&L'!B26 | D6: ='P&L'!C26 | E6: ='P&L'!D26 | F6: ='P&L'!E26 | G6: ='P&L'!F26
A7: การเปลี่ยนแปลงทุนหมุนเวียน | B7: 0 | C7: =Assumptions!$B$62 | D7: =Assumptions!$B$63 | E7: =Assumptions!$B$64 | F7: =Assumptions!$B$65 | G7: =Assumptions!$B$66
A8: รวมกระแสเงินสดจากการดำเนินงาน | B8: =B5+B6+B7 | C8: =C5+C6+C7 | D8: =D5+D6+D7 | E8: =E5+E6+E7 | F8: =F5+F6+F7 | G8: =G5+G6+G7
A10: กระแสเงินสดจากการลงทุน
A11: การลงทุนเริ่มต้น (สินทรัพย์) | B11: =-Assumptions!$B$45 | C11: 0 | D11: 0 | E11: 0 | F11: 0 | G11: 0
A12: CapEx เพิ่มเติม | B12: 0 | C12: =Assumptions!$B$67 | D12: =Assumptions!$B$68 | E12: =Assumptions!$B$69 | F12: =Assumptions!$B$70 | G12: =Assumptions!$B$71
A13: รวมกระแสเงินสดจากการลงทุน | B13: =B11+B12 | C13: =C11+C12 | D13: =D11+D12 | E13: =E11+E12 | F13: =F11+F12 | G13: =G11+G12
A15: กระแสเงินสดจากกิจกรรมทางการเงิน
A16: เงินทุนผู้ถือหุ้น | B16: =Assumptions!$B$39 | C16: 0 | D16: 0 | E16: 0 | F16: 0 | G16: 0
A17: เงินกู้ระยะยาว (received) | B17: =Assumptions!$B$40 | C17: 0 | D17: 0 | E17: 0 | F17: 0 | G17: 0
A18: การชำระเงินต้น | B18: 0 | C18: =-Loan!D4 | D18: =-Loan!D5 | E18: =-Loan!D6 | F18: =-Loan!D7 | G18: =-Loan!D8
A19: การจ่ายปันผล | B19: 0 | C19: =-'P&L'!B34 | D19: =-'P&L'!C34 | E19: =-'P&L'!D34 | F19: =-'P&L'!E34 | G19: =-'P&L'!F34
A20: รวมกระแสเงินสดจากกิจกรรมทางการเงิน | B20: =B16+B17+B18+B19 | C20: =C16+C17+C18+C19 | D20: =D16+D17+D18+D19 | E20: =E16+E17+E18+E19 | F20: =F16+F17+F18+F19 | G20: =G16+G17+G18+G19
A22: กระแสเงินสดสุทธิเปลี่ยนแปลง | B22: =B8+B13+B20 | C22: =C8+C13+C20 | D22: =D8+D13+D20 | E22: =E8+E13+E20 | F22: =F8+F13+F20 | G22: =G8+G13+G20
A23: เงินสดคงเหลือสะสม ณ สิ้นงวด | B23: =B22 | C23: =B23+C22 | D23: =C23+D22 | E23: =D23+E22 | F23: =E23+F22 | G23: =F23+G22

Sheet BalanceSheet
A1: งบแสดงฐานะทางการเงิน 5 ปี
A2: กำไรสะสมคำนวณเป็น plug เพื่อให้ Balance Sheet สมดุล
A4: รายการ | B4: ปีที่ 0 | C4: ปีที่ 1 | D4: ปีที่ 2 | E4: ปีที่ 3 | F4: ปีที่ 4 | G4: ปีที่ 5
A5: สินทรัพย์หมุนเวียน
A6: เงินสด | B6: =CashFlow!B23 | C6: =CashFlow!C23 | D6: =CashFlow!D23 | E6: =CashFlow!E23 | F6: =CashFlow!F23 | G6: =CashFlow!G23
A7: ลูกหนี้การค้า (input) | B7: 0 | C7: 80000 | D7: 200000 | E7: 280000 | F7: 340000 | G7: 400000
A8: รวมสินทรัพย์หมุนเวียน | B8: =B6+B7 | C8: =C6+C7 | D8: =D6+D7 | E8: =E6+E7 | F8: =F6+F7 | G8: =G6+G7
A10: สินทรัพย์ไม่หมุนเวียน
A11: อุปกรณ์ (net) | B11: 150000 | C11: 170000 | D11: 220000 | E11: 290000 | F11: 310000 | G11: 330000
A12: ซอฟต์แวร์ (net) | B12: 300000 | C12: 200000 | D12: 100000 | E12: 0 | F12: 0 | G12: 0
A13: ตราสินค้า (net) | B13: 30000 | C13: 24000 | D13: 18000 | E13: 12000 | F13: 6000 | G13: 0
A14: รวมสินทรัพย์ไม่หมุนเวียน | B14: =SUM(B11:B13) | C14: =SUM(C11:C13) | D14: =SUM(D11:D13) | E14: =SUM(E11:E13) | F14: =SUM(F11:F13) | G14: =SUM(G11:G13)
A16: รวมสินทรัพย์ | B16: =B8+B14 | C16: =C8+C14 | D16: =D8+D14 | E16: =E8+E14 | F16: =F8+F14 | G16: =G8+G14
A18: หนี้สินหมุนเวียน
A19: เจ้าหนี้การค้า (input) | B19: 0 | C19: 30000 | D19: 60000 | E19: 80000 | F19: 100000 | G19: 120000
A20: ค่าใช้จ่ายค้างจ่าย (input) | B20: 0 | C20: 20000 | D20: 40000 | E20: 60000 | F20: 80000 | G20: 100000
A21: ภาษีค้างจ่าย (link P&L) | B21: 0 | C21: ='P&L'!B30 | D21: ='P&L'!C30 | E21: ='P&L'!D30 | F21: ='P&L'!E30 | G21: ='P&L'!F30
A22: รวมหนี้สินหมุนเวียน | B22: =SUM(B19:B21) | C22: =SUM(C19:C21) | D22: =SUM(D19:D21) | E22: =SUM(E19:E21) | F22: =SUM(F19:F21) | G22: =SUM(G19:G21)
A24: หนี้สินไม่หมุนเวียน
A25: เงินกู้ระยะยาว (จาก Loan sheet) | B25: =Assumptions!$B$40 | C25: =Loan!F4 | D25: =Loan!F5 | E25: =Loan!F6 | F25: =Loan!F7 | G25: =Loan!F8
A26: รวมหนี้สิน | B26: =B22+B25 | C26: =C22+C25 | D26: =D22+D25 | E26: =E22+E25 | F26: =F22+F25 | G26: =G22+G25
A28: ส่วนของผู้ถือหุ้น
A29: ทุนจดทะเบียน | B29: =Assumptions!$B$39 | C29: =Assumptions!$B$39 | D29: =Assumptions!$B$39 | E29: =Assumptions!$B$39 | F29: =Assumptions!$B$39 | G29: =Assumptions!$B$39
A30: กำไรสะสม (plug) | B30: =B16-B26-B29 | C30: =C16-C26-C29 | D30: =D16-D26-D29 | E30: =E16-E26-E29 | F30: =F16-F26-F29 | G30: =G16-G26-G29
A31: รวมส่วนของผู้ถือหุ้น | B31: =B29+B30 | C31: =C29+C30 | D31: =D29+D30 | E31: =E29+E30 | F31: =F29+F30 | G31: =G29+G30
A33: รวมหนี้สิน + ส่วนของผู้ถือหุ้น | B33: =B26+B31 | C33: =C26+C31 | D33: =D26+D31 | E33: =E26+E31 | F33: =F26+F31 | G33: =G26+G31

Sheet BreakEven
A1: การวิเคราะห์จุดคุ้มทุน
A3: รายการ | B3: ค่า | C3: คำอธิบาย
A4: Contribution margin/tenant/mo | B4: =Assumptions!$B$12-Assumptions!$B$27 | C4: รายได้ - ต้นทุนผันแปร
A5: ต้นทุนคงที่/mo (system + salary Y1) | B5: =Assumptions!$B$28+Assumptions!$B$29
A6: จำนวน tenant ที่จุดคุ้มทุน | B6: =ROUNDUP(B5/B4,0) | C6: fixed / contribution
A7: เดือนถึงจุดคุ้มทุน (Y1 growth) | B7: =ROUNDUP(B6/Assumptions!$B$32,0) | C7: be / growth

Sheet Sensitivity
A1: การวิเคราะห์ความอ่อนไหว
A3: ตัวแปร | B3: Worst | C3: Base | D3: Best
A4: Tenant ใหม่/mo | B4: 1 | C4: 2 | D4: 3
A5: สัดส่วน Starter | B5: 0.8 | C5: 0.6 | D5: 0.4
A6: สัดส่วน Pro | B6: 0.15 | C6: 0.3 | D6: 0.4
A7: สัดส่วน Enterprise | B7: 0.05 | C7: 0.1 | D7: 0.2
A9: รายได้เฉลี่ย/tenant/mo | B9: =B5*Assumptions!$B$5+B6*Assumptions!$B$6+B7*Assumptions!$B$7 | C9: =C5*Assumptions!$B$5+C6*Assumptions!$B$6+C7*Assumptions!$B$7 | D9: =D5*Assumptions!$B$5+D6*Assumptions!$B$6+D7*Assumptions!$B$7
A10: Tenant ณ สิ้นปี 5 | B10: =B4*60 | C10: =C4*60 | D10: =D4*60

Sheet Summary
A1: บทสรุปทางการเงิน (NPV/IRR/MIRR/Payback)
A3: Project Cash Flows for NPV/IRR | B3: Y0-Y5
A4: Y0 Initial Investment (equity + loan) | B4: =-(Assumptions!$B$39+Assumptions!$B$40)
A5: Y1 NCF = OCF + ICF | B5: =CashFlow!C8+CashFlow!C13
A6: Y2 NCF = OCF + ICF | B6: =CashFlow!D8+CashFlow!D13
A7: Y3 NCF = OCF + ICF | B7: =CashFlow!E8+CashFlow!E13
A8: Y4 NCF = OCF + ICF | B8: =CashFlow!F8+CashFlow!F13
A9: Y5 NCF = OCF + ICF | B9: =CashFlow!G8+CashFlow!G13
A11: ตัวชี้วัด | B11: ค่า | C11: การประเมิน
A12: NPV (WACC 12%) | B12: =B4+NPV(Assumptions!$B$38,B5:B9) | C12: บวก=ลงทุนแล้วสร้างมูลค่า
A13: IRR | B13: =IRR(B4:B9) | C13: ต้อง > WACC (12%)
A14: MIRR (reinvest 5%, finance 12%) | B14: =MIRR(B4:B9,Assumptions!$B$38,0.05) | C14: IRR ปรับแล้วด้วยอัตรา reinvest จริง
A15: Payback Period (base case) | B15: ~2.78 ปี | C15: simple payback (ดูตาราง cumulative CF ด้านบน)
A16: รายได้ปีที่ 1 | B16: ='P&L'!B10
A17: รายได้ปีที่ 5 | B17: ='P&L'!F10
A18: กำไรสุทธิปีที่ 1 | B18: ='P&L'!B31
A19: กำไรสุทธิปีที่ 5 | B19: ='P&L'!F31
A20: เงินสดสะสมสิ้นปีที่ 5 | B20: =CashFlow!G23
A21: เงินทุนเริ่มต้นรวม | B21: =Assumptions!$B$39+Assumptions!$B$40 | C21: equity 2M + debt 1M
A22: จำนวน tenant ณ สิ้นปี 5 | B22: ='P&L'!F4
